<?xml version="1.0"?>
<robot name="simple_robot">
  <!-- 기본 재료 정의 -->
  <material name="gray">
    <color rgba="0.7 0.7 0.7 1"/>
  </material>
  <material name="black">
    <color rgba="0 0 0 1"/>
  </material>
  <material name="white">
    <color rgba="1 1 1 1"/>
  </material>

  <!-- Base link -->
  <link name="base_footprint" />
  <link name="base_link">
    <visual>
      <geometry>
        <box size="0.6 0.6 0.4" />
      </geometry>
      <origin xyz="0 0 0.2" rpy="0 0 0" />
      <material name="gray" />
    </visual>
  </link>

  <!-- Lidar link -->
  <link name="lidar">
    <visual>
      <geometry>
        <cylinder radius="0.1" length="0.05" />
      </geometry>
      <origin xyz="0 0 0" rpy="0 0 0" />
      <material name="white" />
    </visual>
  </link>

  <!-- Left wheel link -->
  <link name="left_wheel">
    <visual>
      <geometry>
        <cylinder radius="0.0965" length="0.1" />
      </geometry>
      <origin xyz="0 0 0" rpy="1.57 0 0" />
      <material name="gray" />
    </visual>
  </link>

  <!-- Right wheel link -->
  <link name="right_wheel">
    <visual>
      <geometry>
        <cylinder radius="0.0965" length="0.1" />
      </geometry>
      <origin xyz="0 0 0" rpy="1.57 0 0" />
      <material name="gray" />
    </visual>
  </link>

  <!-- Caster wheel link -->
  <link name="caster_wheel">
    <visual>
      <geometry>
        <sphere radius="0.05" />
      </geometry>
      <origin xyz="0 0 0" rpy="0 0 0" />
      <material name="gray" />
    </visual>
  </link>

  <!-- Joints -->
  <joint name="base_joint" type="fixed">
    <parent link="base_footprint" />
    <child link="base_link" />
    <origin xyz="0 0 0.1" rpy="0 0 0" />
  </joint>

  <joint name="base_lidar_joint" type="fixed">
    <parent link="base_link" />
    <child link="lidar" />
    <origin xyz="0.3 0 0" rpy="0 0 3.14159" />
  </joint>

  <joint name="base_left_wheel_joint" type="continuous">
    <parent link="base_link" />
    <child link="left_wheel" />
    <origin xyz="-0.25 0.3 0" rpy="0 0 0" />
    <axis xyz="0 1 0" />
  </joint>

  <joint name="base_right_wheel_joint" type="continuous">
    <parent link="base_link" />
    <child link="right_wheel" />
    <origin xyz="-0.25 -0.3 0" rpy="0 0 0" />
    <axis xyz="0 1 0" />
  </joint>

  <joint name="base_caster_wheel_joint" type="fixed">
    <parent link="base_link" />
    <child link="caster_wheel" />
    <origin xyz="0.2 0 -0.05" rpy="0 0 0" />
    <axis xyz="0 0 1" /> <!-- 회전 축을 Z축으로 수정 -->
  </joint>

  <!-- base_footprint와 base_link 간의 변환 정의 추가 -->
  <joint name="base_link_to_footprint" type="fixed">
    <parent link="base_footprint"/>
    <child link="base_link"/>
    <origin xyz="0 0 0" rpy="0 0 0"/>
  </joint>

</robot>
